const catchAsyncError=(thefunc)=>(req,res,next)=>{



    Promise.resolve(thefunc(req,res,next).catch(next))

}



module.exports={catchAsyncError}